{"uuid": "eb32c67a-963e-4592-b731-2f790c396e5f", "children": ["a935620f-e347-4569-a660-a6071607585a", "ef6a1244-003e-4c84-8b88-c459cdfe1b42", "d7790f82-36fa-4ab8-bb79-260a1bddf708"], "befores": [{"name": "test_setup", "status": "passed", "start": 1566924045056, "stop": 1566924057232}], "afters": [{"name": "test_setup::0", "status": "broken", "statusDetails": {"message": "urllib3.exceptions.MaxRetryError: HTTPConnectionPool(host='127.0.0.1', port=51281): Max retries exceeded with url: /session/ded295aae16c502e32ce62307d00f64d/window (Caused by NewConnectionError('<urllib3.connection.HTTPConnection object at 0x103139a58>: Failed to establish a new connection: [Errno 61] Connection refused'))\n", "trace": "  File \"/Users/dilip.chauhan/Desktop/ActitimeFramework/venv/lib/python3.7/site-packages/allure_commons/_allure.py\", line 185, in __call__\n    return self._fixture_function(*args, **kwargs)\n  File \"/Users/dilip.chauhan/Desktop/ActitimeFramework/venv/lib/python3.7/site-packages/_pytest/fixtures.py\", line 786, in _teardown_yield_fixture\n    next(it)\n  File \"/Users/dilip.chauhan/Desktop/ActitimeFramework/conftest.py\", line 24, in test_setup\n    driver.close()\n  File \"/Users/dilip.chauhan/Desktop/ActitimeFramework/venv/lib/python3.7/site-packages/selenium/webdriver/remote/webdriver.py\", line 688, in close\n    self.execute(Command.CLOSE)\n  File \"/Users/dilip.chauhan/Desktop/ActitimeFramework/venv/lib/python3.7/site-packages/selenium/webdriver/remote/webdriver.py\", line 319, in execute\n    response = self.command_executor.execute(driver_command, params)\n  File \"/Users/dilip.chauhan/Desktop/ActitimeFramework/venv/lib/python3.7/site-packages/selenium/webdriver/remote/remote_connection.py\", line 374, in execute\n    return self._request(command_info[0], url, body=data)\n  File \"/Users/dilip.chauhan/Desktop/ActitimeFramework/venv/lib/python3.7/site-packages/selenium/webdriver/remote/remote_connection.py\", line 397, in _request\n    resp = self._conn.request(method, url, body=body, headers=headers)\n  File \"/Users/dilip.chauhan/Desktop/ActitimeFramework/venv/lib/python3.7/site-packages/urllib3/request.py\", line 68, in request\n    **urlopen_kw)\n  File \"/Users/dilip.chauhan/Desktop/ActitimeFramework/venv/lib/python3.7/site-packages/urllib3/request.py\", line 89, in request_encode_url\n    return self.urlopen(method, url, **extra_kw)\n  File \"/Users/dilip.chauhan/Desktop/ActitimeFramework/venv/lib/python3.7/site-packages/urllib3/poolmanager.py\", line 326, in urlopen\n    response = conn.urlopen(method, u.request_uri, **kw)\n  File \"/Users/dilip.chauhan/Desktop/ActitimeFramework/venv/lib/python3.7/site-packages/urllib3/connectionpool.py\", line 670, in urlopen\n    **response_kw)\n  File \"/Users/dilip.chauhan/Desktop/ActitimeFramework/venv/lib/python3.7/site-packages/urllib3/connectionpool.py\", line 670, in urlopen\n    **response_kw)\n  File \"/Users/dilip.chauhan/Desktop/ActitimeFramework/venv/lib/python3.7/site-packages/urllib3/connectionpool.py\", line 670, in urlopen\n    **response_kw)\n  File \"/Users/dilip.chauhan/Desktop/ActitimeFramework/venv/lib/python3.7/site-packages/urllib3/connectionpool.py\", line 641, in urlopen\n    _stacktrace=sys.exc_info()[2])\n  File \"/Users/dilip.chauhan/Desktop/ActitimeFramework/venv/lib/python3.7/site-packages/urllib3/util/retry.py\", line 399, in increment\n    raise MaxRetryError(_pool, url, error or ResponseError(cause))\n"}, "start": 1566924066699, "stop": 1566924066999}], "start": 1566924045056, "stop": 1566924066999}